WARNING 2022-04-22 15:54:15,039 log 3048 6208778240 Not Found: /favicon.ico
ERROR 2022-04-24 17:20:12,033 log 11248 6241120256 Internal Server Error: /v1/articles/
Traceback (most recent call last):
  File "/Users/lijialin/myproject-flask/venv/lib/python3.8/site-packages/django/core/handlers/exception.py", line 34, in inner
    response = get_response(request)
  File "/Users/lijialin/myproject-flask/venv/lib/python3.8/site-packages/django/core/handlers/base.py", line 145, in _get_response
    response = self.process_exception_by_middleware(e, request)
  File "/Users/lijialin/myproject-flask/venv/lib/python3.8/site-packages/django/core/handlers/base.py", line 143, in _get_response
    response = response.render()
  File "/Users/lijialin/myproject-flask/venv/lib/python3.8/site-packages/django/template/response.py", line 106, in render
    self.content = self.rendered_content
  File "/Users/lijialin/myproject-flask/venv/lib/python3.8/site-packages/rest_framework/response.py", line 70, in rendered_content
    ret = renderer.render(self.data, accepted_media_type, context)
  File "/Users/lijialin/myproject-flask/venv/lib/python3.8/site-packages/rest_framework/renderers.py", line 723, in render
    template = loader.get_template(self.template)
  File "/Users/lijialin/myproject-flask/venv/lib/python3.8/site-packages/django/template/loader.py", line 19, in get_template
    raise TemplateDoesNotExist(template_name, chain=chain)
django.template.exceptions.TemplateDoesNotExist: rest_framework/api.html
ERROR 2022-04-24 17:20:55,665 log 11248 6241120256 Internal Server Error: /v1/articles/
Traceback (most recent call last):
  File "/Users/lijialin/myproject-flask/venv/lib/python3.8/site-packages/django/core/handlers/exception.py", line 34, in inner
    response = get_response(request)
  File "/Users/lijialin/myproject-flask/venv/lib/python3.8/site-packages/django/core/handlers/base.py", line 145, in _get_response
    response = self.process_exception_by_middleware(e, request)
  File "/Users/lijialin/myproject-flask/venv/lib/python3.8/site-packages/django/core/handlers/base.py", line 143, in _get_response
    response = response.render()
  File "/Users/lijialin/myproject-flask/venv/lib/python3.8/site-packages/django/template/response.py", line 106, in render
    self.content = self.rendered_content
  File "/Users/lijialin/myproject-flask/venv/lib/python3.8/site-packages/rest_framework/response.py", line 70, in rendered_content
    ret = renderer.render(self.data, accepted_media_type, context)
  File "/Users/lijialin/myproject-flask/venv/lib/python3.8/site-packages/rest_framework/renderers.py", line 723, in render
    template = loader.get_template(self.template)
  File "/Users/lijialin/myproject-flask/venv/lib/python3.8/site-packages/django/template/loader.py", line 19, in get_template
    raise TemplateDoesNotExist(template_name, chain=chain)
django.template.exceptions.TemplateDoesNotExist: rest_framework/api.html
WARNING 2022-04-24 17:52:32,917 log 11552 6284455936 Not Found: /v1/articles/3
WARNING 2022-04-24 17:56:11,717 log 11552 6284455936 Bad Request: /v1/articles/
WARNING 2022-04-24 17:58:39,039 log 11552 6284455936 Bad Request: /v1/articles/
WARNING 2022-04-24 18:04:20,137 log 11775 6215151616 Bad Request: /v1/articles/
WARNING 2022-04-24 18:16:09,531 log 11775 6215151616 Not Found: /openapi.json
ERROR 2022-04-24 18:18:02,299 log 11957 6221934592 Internal Server Error: /v1/articles/
Traceback (most recent call last):
  File "/Users/lijialin/myproject-flask/venv/lib/python3.8/site-packages/django/core/handlers/exception.py", line 34, in inner
    response = get_response(request)
  File "/Users/lijialin/myproject-flask/venv/lib/python3.8/site-packages/django/core/handlers/base.py", line 115, in _get_response
    response = self.process_exception_by_middleware(e, request)
  File "/Users/lijialin/myproject-flask/venv/lib/python3.8/site-packages/django/core/handlers/base.py", line 113, in _get_response
    response = wrapped_callback(request, *callback_args, **callback_kwargs)
  File "/Users/lijialin/myproject-flask/venv/lib/python3.8/site-packages/django/views/decorators/csrf.py", line 54, in wrapped_view
    return view_func(*args, **kwargs)
  File "/Users/lijialin/myproject-flask/venv/lib/python3.8/site-packages/django/views/generic/base.py", line 71, in view
    return self.dispatch(request, *args, **kwargs)
  File "/Users/lijialin/myproject-flask/venv/lib/python3.8/site-packages/rest_framework/views.py", line 509, in dispatch
    response = self.handle_exception(exc)
  File "/Users/lijialin/myproject-flask/venv/lib/python3.8/site-packages/rest_framework/views.py", line 469, in handle_exception
    self.raise_uncaught_exception(exc)
  File "/Users/lijialin/myproject-flask/venv/lib/python3.8/site-packages/rest_framework/views.py", line 480, in raise_uncaught_exception
    raise exc
  File "/Users/lijialin/myproject-flask/venv/lib/python3.8/site-packages/rest_framework/views.py", line 506, in dispatch
    response = handler(request, *args, **kwargs)
  File "/Users/lijialin/myproject-flask/venv/lib/python3.8/site-packages/rest_framework/decorators.py", line 50, in handler
    return func(*args, **kwargs)
  File "/Users/lijialin/myblog/drf/views.py", line 22, in article_list
    serializer.save(author=request.user)
  File "/Users/lijialin/myproject-flask/venv/lib/python3.8/site-packages/rest_framework/serializers.py", line 212, in save
    self.instance = self.create(validated_data)
  File "/Users/lijialin/myproject-flask/venv/lib/python3.8/site-packages/rest_framework/serializers.py", line 177, in create
    raise NotImplementedError('`create()` must be implemented.')
NotImplementedError: `create()` must be implemented.
ERROR 2022-04-27 16:27:22,696 log 22697 6216216576 Internal Server Error: /v1/articles/
Traceback (most recent call last):
  File "/Users/lijialin/myproject-flask/venv/lib/python3.8/site-packages/django/core/handlers/exception.py", line 34, in inner
    response = get_response(request)
  File "/Users/lijialin/myproject-flask/venv/lib/python3.8/site-packages/django/core/handlers/base.py", line 115, in _get_response
    response = self.process_exception_by_middleware(e, request)
  File "/Users/lijialin/myproject-flask/venv/lib/python3.8/site-packages/django/core/handlers/base.py", line 113, in _get_response
    response = wrapped_callback(request, *callback_args, **callback_kwargs)
  File "/Users/lijialin/myproject-flask/venv/lib/python3.8/site-packages/django/views/decorators/csrf.py", line 54, in wrapped_view
    return view_func(*args, **kwargs)
  File "/Users/lijialin/myproject-flask/venv/lib/python3.8/site-packages/django/views/generic/base.py", line 71, in view
    return self.dispatch(request, *args, **kwargs)
  File "/Users/lijialin/myproject-flask/venv/lib/python3.8/site-packages/rest_framework/views.py", line 509, in dispatch
    response = self.handle_exception(exc)
  File "/Users/lijialin/myproject-flask/venv/lib/python3.8/site-packages/rest_framework/views.py", line 469, in handle_exception
    self.raise_uncaught_exception(exc)
  File "/Users/lijialin/myproject-flask/venv/lib/python3.8/site-packages/rest_framework/views.py", line 480, in raise_uncaught_exception
    raise exc
  File "/Users/lijialin/myproject-flask/venv/lib/python3.8/site-packages/rest_framework/views.py", line 506, in dispatch
    response = handler(request, *args, **kwargs)
  File "/Users/lijialin/myblog/drf/views.py", line 32, in get
    return Response(serializer.data)
  File "/Users/lijialin/myproject-flask/venv/lib/python3.8/site-packages/rest_framework/serializers.py", line 768, in data
    ret = super().data
  File "/Users/lijialin/myproject-flask/venv/lib/python3.8/site-packages/rest_framework/serializers.py", line 253, in data
    self._data = self.to_representation(self.instance)
  File "/Users/lijialin/myproject-flask/venv/lib/python3.8/site-packages/rest_framework/serializers.py", line 686, in to_representation
    return [
  File "/Users/lijialin/myproject-flask/venv/lib/python3.8/site-packages/rest_framework/serializers.py", line 687, in <listcomp>
    self.child.to_representation(item) for item in iterable
  File "/Users/lijialin/myblog/drf/serializers.py", line 67, in to_representation
    data['count'] = instance.count()
AttributeError: 'drf_Article' object has no attribute 'count'
ERROR 2022-04-27 16:52:07,590 log 22954 6253539328 Internal Server Error: /v1/articles/
Traceback (most recent call last):
  File "/Users/lijialin/myproject-flask/venv/lib/python3.8/site-packages/django/core/handlers/exception.py", line 34, in inner
    response = get_response(request)
  File "/Users/lijialin/myproject-flask/venv/lib/python3.8/site-packages/django/core/handlers/base.py", line 115, in _get_response
    response = self.process_exception_by_middleware(e, request)
  File "/Users/lijialin/myproject-flask/venv/lib/python3.8/site-packages/django/core/handlers/base.py", line 113, in _get_response
    response = wrapped_callback(request, *callback_args, **callback_kwargs)
  File "/Users/lijialin/myproject-flask/venv/lib/python3.8/site-packages/django/views/decorators/csrf.py", line 54, in wrapped_view
    return view_func(*args, **kwargs)
  File "/Users/lijialin/myproject-flask/venv/lib/python3.8/site-packages/django/views/generic/base.py", line 71, in view
    return self.dispatch(request, *args, **kwargs)
  File "/Users/lijialin/myproject-flask/venv/lib/python3.8/site-packages/rest_framework/views.py", line 509, in dispatch
    response = self.handle_exception(exc)
  File "/Users/lijialin/myproject-flask/venv/lib/python3.8/site-packages/rest_framework/views.py", line 469, in handle_exception
    self.raise_uncaught_exception(exc)
  File "/Users/lijialin/myproject-flask/venv/lib/python3.8/site-packages/rest_framework/views.py", line 480, in raise_uncaught_exception
    raise exc
  File "/Users/lijialin/myproject-flask/venv/lib/python3.8/site-packages/rest_framework/views.py", line 506, in dispatch
    response = handler(request, *args, **kwargs)
  File "/Users/lijialin/myblog/drf/views.py", line 32, in get
    return Response(serializer.data)
  File "/Users/lijialin/myproject-flask/venv/lib/python3.8/site-packages/rest_framework/serializers.py", line 768, in data
    ret = super().data
  File "/Users/lijialin/myproject-flask/venv/lib/python3.8/site-packages/rest_framework/serializers.py", line 253, in data
    self._data = self.to_representation(self.instance)
  File "/Users/lijialin/myproject-flask/venv/lib/python3.8/site-packages/rest_framework/serializers.py", line 686, in to_representation
    return [
  File "/Users/lijialin/myproject-flask/venv/lib/python3.8/site-packages/rest_framework/serializers.py", line 687, in <listcomp>
    self.child.to_representation(item) for item in iterable
  File "/Users/lijialin/myproject-flask/venv/lib/python3.8/site-packages/rest_framework/serializers.py", line 522, in to_representation
    ret[field.field_name] = field.to_representation(attribute)
  File "/Users/lijialin/myproject-flask/venv/lib/python3.8/site-packages/rest_framework/serializers.py", line 509, in to_representation
    attribute = field.get_attribute(instance)
  File "/Users/lijialin/myproject-flask/venv/lib/python3.8/site-packages/rest_framework/relations.py", line 538, in get_attribute
    relationship = get_attribute(instance, self.source_attrs)
  File "/Users/lijialin/myproject-flask/venv/lib/python3.8/site-packages/rest_framework/fields.py", line 97, in get_attribute
    instance = getattr(instance, attr)
AttributeError: 'User' object has no attribute 'articles'
ERROR 2022-04-27 16:52:56,808 log 22966 6290141184 Internal Server Error: /v1/articles/
Traceback (most recent call last):
  File "/Users/lijialin/myproject-flask/venv/lib/python3.8/site-packages/django/core/handlers/exception.py", line 34, in inner
    response = get_response(request)
  File "/Users/lijialin/myproject-flask/venv/lib/python3.8/site-packages/django/core/handlers/base.py", line 115, in _get_response
    response = self.process_exception_by_middleware(e, request)
  File "/Users/lijialin/myproject-flask/venv/lib/python3.8/site-packages/django/core/handlers/base.py", line 113, in _get_response
    response = wrapped_callback(request, *callback_args, **callback_kwargs)
  File "/Users/lijialin/myproject-flask/venv/lib/python3.8/site-packages/django/views/decorators/csrf.py", line 54, in wrapped_view
    return view_func(*args, **kwargs)
  File "/Users/lijialin/myproject-flask/venv/lib/python3.8/site-packages/django/views/generic/base.py", line 71, in view
    return self.dispatch(request, *args, **kwargs)
  File "/Users/lijialin/myproject-flask/venv/lib/python3.8/site-packages/rest_framework/views.py", line 509, in dispatch
    response = self.handle_exception(exc)
  File "/Users/lijialin/myproject-flask/venv/lib/python3.8/site-packages/rest_framework/views.py", line 469, in handle_exception
    self.raise_uncaught_exception(exc)
  File "/Users/lijialin/myproject-flask/venv/lib/python3.8/site-packages/rest_framework/views.py", line 480, in raise_uncaught_exception
    raise exc
  File "/Users/lijialin/myproject-flask/venv/lib/python3.8/site-packages/rest_framework/views.py", line 506, in dispatch
    response = handler(request, *args, **kwargs)
  File "/Users/lijialin/myblog/drf/views.py", line 32, in get
    return Response(serializer.data)
  File "/Users/lijialin/myproject-flask/venv/lib/python3.8/site-packages/rest_framework/serializers.py", line 768, in data
    ret = super().data
  File "/Users/lijialin/myproject-flask/venv/lib/python3.8/site-packages/rest_framework/serializers.py", line 253, in data
    self._data = self.to_representation(self.instance)
  File "/Users/lijialin/myproject-flask/venv/lib/python3.8/site-packages/rest_framework/serializers.py", line 686, in to_representation
    return [
  File "/Users/lijialin/myproject-flask/venv/lib/python3.8/site-packages/rest_framework/serializers.py", line 687, in <listcomp>
    self.child.to_representation(item) for item in iterable
  File "/Users/lijialin/myproject-flask/venv/lib/python3.8/site-packages/rest_framework/serializers.py", line 522, in to_representation
    ret[field.field_name] = field.to_representation(attribute)
  File "/Users/lijialin/myproject-flask/venv/lib/python3.8/site-packages/rest_framework/serializers.py", line 509, in to_representation
    attribute = field.get_attribute(instance)
  File "/Users/lijialin/myproject-flask/venv/lib/python3.8/site-packages/rest_framework/relations.py", line 538, in get_attribute
    relationship = get_attribute(instance, self.source_attrs)
  File "/Users/lijialin/myproject-flask/venv/lib/python3.8/site-packages/rest_framework/fields.py", line 97, in get_attribute
    instance = getattr(instance, attr)
AttributeError: 'User' object has no attribute 'articles'
ERROR 2022-04-27 16:55:37,878 log 23013 6259716096 Internal Server Error: /v1/articles/
Traceback (most recent call last):
  File "/Users/lijialin/myproject-flask/venv/lib/python3.8/site-packages/django/core/handlers/exception.py", line 34, in inner
    response = get_response(request)
  File "/Users/lijialin/myproject-flask/venv/lib/python3.8/site-packages/django/core/handlers/base.py", line 115, in _get_response
    response = self.process_exception_by_middleware(e, request)
  File "/Users/lijialin/myproject-flask/venv/lib/python3.8/site-packages/django/core/handlers/base.py", line 113, in _get_response
    response = wrapped_callback(request, *callback_args, **callback_kwargs)
  File "/Users/lijialin/myproject-flask/venv/lib/python3.8/site-packages/django/views/decorators/csrf.py", line 54, in wrapped_view
    return view_func(*args, **kwargs)
  File "/Users/lijialin/myproject-flask/venv/lib/python3.8/site-packages/django/views/generic/base.py", line 71, in view
    return self.dispatch(request, *args, **kwargs)
  File "/Users/lijialin/myproject-flask/venv/lib/python3.8/site-packages/rest_framework/views.py", line 509, in dispatch
    response = self.handle_exception(exc)
  File "/Users/lijialin/myproject-flask/venv/lib/python3.8/site-packages/rest_framework/views.py", line 469, in handle_exception
    self.raise_uncaught_exception(exc)
  File "/Users/lijialin/myproject-flask/venv/lib/python3.8/site-packages/rest_framework/views.py", line 480, in raise_uncaught_exception
    raise exc
  File "/Users/lijialin/myproject-flask/venv/lib/python3.8/site-packages/rest_framework/views.py", line 506, in dispatch
    response = handler(request, *args, **kwargs)
  File "/Users/lijialin/myblog/drf/views.py", line 32, in get
    return Response(serializer.data)
  File "/Users/lijialin/myproject-flask/venv/lib/python3.8/site-packages/rest_framework/serializers.py", line 768, in data
    ret = super().data
  File "/Users/lijialin/myproject-flask/venv/lib/python3.8/site-packages/rest_framework/serializers.py", line 253, in data
    self._data = self.to_representation(self.instance)
  File "/Users/lijialin/myproject-flask/venv/lib/python3.8/site-packages/rest_framework/serializers.py", line 686, in to_representation
    return [
  File "/Users/lijialin/myproject-flask/venv/lib/python3.8/site-packages/rest_framework/serializers.py", line 687, in <listcomp>
    self.child.to_representation(item) for item in iterable
  File "/Users/lijialin/myproject-flask/venv/lib/python3.8/site-packages/rest_framework/serializers.py", line 522, in to_representation
    ret[field.field_name] = field.to_representation(attribute)
  File "/Users/lijialin/myproject-flask/venv/lib/python3.8/site-packages/rest_framework/serializers.py", line 509, in to_representation
    attribute = field.get_attribute(instance)
  File "/Users/lijialin/myproject-flask/venv/lib/python3.8/site-packages/rest_framework/relations.py", line 538, in get_attribute
    relationship = get_attribute(instance, self.source_attrs)
  File "/Users/lijialin/myproject-flask/venv/lib/python3.8/site-packages/rest_framework/fields.py", line 97, in get_attribute
    instance = getattr(instance, attr)
AttributeError: 'User' object has no attribute 'articles'
ERROR 2022-04-27 16:59:30,908 log 23069 6285176832 Internal Server Error: /v1/articles/
Traceback (most recent call last):
  File "/Users/lijialin/myproject-flask/venv/lib/python3.8/site-packages/django/core/handlers/exception.py", line 34, in inner
    response = get_response(request)
  File "/Users/lijialin/myproject-flask/venv/lib/python3.8/site-packages/django/core/handlers/base.py", line 115, in _get_response
    response = self.process_exception_by_middleware(e, request)
  File "/Users/lijialin/myproject-flask/venv/lib/python3.8/site-packages/django/core/handlers/base.py", line 113, in _get_response
    response = wrapped_callback(request, *callback_args, **callback_kwargs)
  File "/Users/lijialin/myproject-flask/venv/lib/python3.8/site-packages/django/views/decorators/csrf.py", line 54, in wrapped_view
    return view_func(*args, **kwargs)
  File "/Users/lijialin/myproject-flask/venv/lib/python3.8/site-packages/django/views/generic/base.py", line 71, in view
    return self.dispatch(request, *args, **kwargs)
  File "/Users/lijialin/myproject-flask/venv/lib/python3.8/site-packages/rest_framework/views.py", line 509, in dispatch
    response = self.handle_exception(exc)
  File "/Users/lijialin/myproject-flask/venv/lib/python3.8/site-packages/rest_framework/views.py", line 469, in handle_exception
    self.raise_uncaught_exception(exc)
  File "/Users/lijialin/myproject-flask/venv/lib/python3.8/site-packages/rest_framework/views.py", line 480, in raise_uncaught_exception
    raise exc
  File "/Users/lijialin/myproject-flask/venv/lib/python3.8/site-packages/rest_framework/views.py", line 506, in dispatch
    response = handler(request, *args, **kwargs)
  File "/Users/lijialin/myblog/drf/views.py", line 32, in get
    return Response(serializer.data)
  File "/Users/lijialin/myproject-flask/venv/lib/python3.8/site-packages/rest_framework/serializers.py", line 768, in data
    ret = super().data
  File "/Users/lijialin/myproject-flask/venv/lib/python3.8/site-packages/rest_framework/serializers.py", line 253, in data
    self._data = self.to_representation(self.instance)
  File "/Users/lijialin/myproject-flask/venv/lib/python3.8/site-packages/rest_framework/serializers.py", line 686, in to_representation
    return [
  File "/Users/lijialin/myproject-flask/venv/lib/python3.8/site-packages/rest_framework/serializers.py", line 687, in <listcomp>
    self.child.to_representation(item) for item in iterable
  File "/Users/lijialin/myproject-flask/venv/lib/python3.8/site-packages/rest_framework/serializers.py", line 522, in to_representation
    ret[field.field_name] = field.to_representation(attribute)
  File "/Users/lijialin/myproject-flask/venv/lib/python3.8/site-packages/rest_framework/serializers.py", line 509, in to_representation
    attribute = field.get_attribute(instance)
  File "/Users/lijialin/myproject-flask/venv/lib/python3.8/site-packages/rest_framework/relations.py", line 538, in get_attribute
    relationship = get_attribute(instance, self.source_attrs)
  File "/Users/lijialin/myproject-flask/venv/lib/python3.8/site-packages/rest_framework/fields.py", line 97, in get_attribute
    instance = getattr(instance, attr)
AttributeError: 'User' object has no attribute 'articles'
ERROR 2022-04-27 17:03:00,379 log 23118 6222278656 Internal Server Error: /v1/articles/
Traceback (most recent call last):
  File "/Users/lijialin/myproject-flask/venv/lib/python3.8/site-packages/django/core/handlers/exception.py", line 34, in inner
    response = get_response(request)
  File "/Users/lijialin/myproject-flask/venv/lib/python3.8/site-packages/django/core/handlers/base.py", line 115, in _get_response
    response = self.process_exception_by_middleware(e, request)
  File "/Users/lijialin/myproject-flask/venv/lib/python3.8/site-packages/django/core/handlers/base.py", line 113, in _get_response
    response = wrapped_callback(request, *callback_args, **callback_kwargs)
  File "/Users/lijialin/myproject-flask/venv/lib/python3.8/site-packages/django/views/decorators/csrf.py", line 54, in wrapped_view
    return view_func(*args, **kwargs)
  File "/Users/lijialin/myproject-flask/venv/lib/python3.8/site-packages/django/views/generic/base.py", line 71, in view
    return self.dispatch(request, *args, **kwargs)
  File "/Users/lijialin/myproject-flask/venv/lib/python3.8/site-packages/rest_framework/views.py", line 509, in dispatch
    response = self.handle_exception(exc)
  File "/Users/lijialin/myproject-flask/venv/lib/python3.8/site-packages/rest_framework/views.py", line 469, in handle_exception
    self.raise_uncaught_exception(exc)
  File "/Users/lijialin/myproject-flask/venv/lib/python3.8/site-packages/rest_framework/views.py", line 480, in raise_uncaught_exception
    raise exc
  File "/Users/lijialin/myproject-flask/venv/lib/python3.8/site-packages/rest_framework/views.py", line 506, in dispatch
    response = handler(request, *args, **kwargs)
  File "/Users/lijialin/myblog/drf/views.py", line 32, in get
    return Response(serializer.data)
  File "/Users/lijialin/myproject-flask/venv/lib/python3.8/site-packages/rest_framework/serializers.py", line 768, in data
    ret = super().data
  File "/Users/lijialin/myproject-flask/venv/lib/python3.8/site-packages/rest_framework/serializers.py", line 253, in data
    self._data = self.to_representation(self.instance)
  File "/Users/lijialin/myproject-flask/venv/lib/python3.8/site-packages/rest_framework/serializers.py", line 686, in to_representation
    return [
  File "/Users/lijialin/myproject-flask/venv/lib/python3.8/site-packages/rest_framework/serializers.py", line 687, in <listcomp>
    self.child.to_representation(item) for item in iterable
  File "/Users/lijialin/myproject-flask/venv/lib/python3.8/site-packages/rest_framework/serializers.py", line 522, in to_representation
    ret[field.field_name] = field.to_representation(attribute)
  File "/Users/lijialin/myproject-flask/venv/lib/python3.8/site-packages/rest_framework/serializers.py", line 509, in to_representation
    attribute = field.get_attribute(instance)
  File "/Users/lijialin/myproject-flask/venv/lib/python3.8/site-packages/rest_framework/relations.py", line 538, in get_attribute
    relationship = get_attribute(instance, self.source_attrs)
  File "/Users/lijialin/myproject-flask/venv/lib/python3.8/site-packages/rest_framework/fields.py", line 97, in get_attribute
    instance = getattr(instance, attr)
AttributeError: 'User' object has no attribute 'articles'
ERROR 2022-04-27 17:33:40,323 log 23404 6253735936 Internal Server Error: /v1/articles/
Traceback (most recent call last):
  File "/Users/lijialin/myproject-flask/venv/lib/python3.8/site-packages/django/core/handlers/exception.py", line 34, in inner
    response = get_response(request)
  File "/Users/lijialin/myproject-flask/venv/lib/python3.8/site-packages/django/core/handlers/base.py", line 115, in _get_response
    response = self.process_exception_by_middleware(e, request)
  File "/Users/lijialin/myproject-flask/venv/lib/python3.8/site-packages/django/core/handlers/base.py", line 113, in _get_response
    response = wrapped_callback(request, *callback_args, **callback_kwargs)
  File "/Users/lijialin/myproject-flask/venv/lib/python3.8/site-packages/django/views/decorators/csrf.py", line 54, in wrapped_view
    return view_func(*args, **kwargs)
  File "/Users/lijialin/myproject-flask/venv/lib/python3.8/site-packages/django/views/generic/base.py", line 71, in view
    return self.dispatch(request, *args, **kwargs)
  File "/Users/lijialin/myproject-flask/venv/lib/python3.8/site-packages/rest_framework/views.py", line 509, in dispatch
    response = self.handle_exception(exc)
  File "/Users/lijialin/myproject-flask/venv/lib/python3.8/site-packages/rest_framework/views.py", line 469, in handle_exception
    self.raise_uncaught_exception(exc)
  File "/Users/lijialin/myproject-flask/venv/lib/python3.8/site-packages/rest_framework/views.py", line 480, in raise_uncaught_exception
    raise exc
  File "/Users/lijialin/myproject-flask/venv/lib/python3.8/site-packages/rest_framework/views.py", line 506, in dispatch
    response = handler(request, *args, **kwargs)
  File "/Users/lijialin/myblog/drf/views.py", line 32, in get
    return Response(serializer.data)
  File "/Users/lijialin/myproject-flask/venv/lib/python3.8/site-packages/rest_framework/serializers.py", line 768, in data
    ret = super().data
  File "/Users/lijialin/myproject-flask/venv/lib/python3.8/site-packages/rest_framework/serializers.py", line 253, in data
    self._data = self.to_representation(self.instance)
  File "/Users/lijialin/myproject-flask/venv/lib/python3.8/site-packages/rest_framework/serializers.py", line 686, in to_representation
    return [
  File "/Users/lijialin/myproject-flask/venv/lib/python3.8/site-packages/rest_framework/serializers.py", line 687, in <listcomp>
    self.child.to_representation(item) for item in iterable
  File "/Users/lijialin/myproject-flask/venv/lib/python3.8/site-packages/rest_framework/serializers.py", line 522, in to_representation
    ret[field.field_name] = field.to_representation(attribute)
  File "/Users/lijialin/myproject-flask/venv/lib/python3.8/site-packages/rest_framework/serializers.py", line 509, in to_representation
    attribute = field.get_attribute(instance)
  File "/Users/lijialin/myproject-flask/venv/lib/python3.8/site-packages/rest_framework/relations.py", line 538, in get_attribute
    relationship = get_attribute(instance, self.source_attrs)
  File "/Users/lijialin/myproject-flask/venv/lib/python3.8/site-packages/rest_framework/fields.py", line 97, in get_attribute
    instance = getattr(instance, attr)
AttributeError: 'User' object has no attribute 'drf_articles'
ERROR 2022-04-27 17:34:16,508 log 23448 6285438976 Internal Server Error: /v1/articles/
Traceback (most recent call last):
  File "/Users/lijialin/myproject-flask/venv/lib/python3.8/site-packages/django/core/handlers/exception.py", line 34, in inner
    response = get_response(request)
  File "/Users/lijialin/myproject-flask/venv/lib/python3.8/site-packages/django/core/handlers/base.py", line 115, in _get_response
    response = self.process_exception_by_middleware(e, request)
  File "/Users/lijialin/myproject-flask/venv/lib/python3.8/site-packages/django/core/handlers/base.py", line 113, in _get_response
    response = wrapped_callback(request, *callback_args, **callback_kwargs)
  File "/Users/lijialin/myproject-flask/venv/lib/python3.8/site-packages/django/views/decorators/csrf.py", line 54, in wrapped_view
    return view_func(*args, **kwargs)
  File "/Users/lijialin/myproject-flask/venv/lib/python3.8/site-packages/django/views/generic/base.py", line 71, in view
    return self.dispatch(request, *args, **kwargs)
  File "/Users/lijialin/myproject-flask/venv/lib/python3.8/site-packages/rest_framework/views.py", line 509, in dispatch
    response = self.handle_exception(exc)
  File "/Users/lijialin/myproject-flask/venv/lib/python3.8/site-packages/rest_framework/views.py", line 469, in handle_exception
    self.raise_uncaught_exception(exc)
  File "/Users/lijialin/myproject-flask/venv/lib/python3.8/site-packages/rest_framework/views.py", line 480, in raise_uncaught_exception
    raise exc
  File "/Users/lijialin/myproject-flask/venv/lib/python3.8/site-packages/rest_framework/views.py", line 506, in dispatch
    response = handler(request, *args, **kwargs)
  File "/Users/lijialin/myblog/drf/views.py", line 32, in get
    return Response(serializer.data)
  File "/Users/lijialin/myproject-flask/venv/lib/python3.8/site-packages/rest_framework/serializers.py", line 768, in data
    ret = super().data
  File "/Users/lijialin/myproject-flask/venv/lib/python3.8/site-packages/rest_framework/serializers.py", line 253, in data
    self._data = self.to_representation(self.instance)
  File "/Users/lijialin/myproject-flask/venv/lib/python3.8/site-packages/rest_framework/serializers.py", line 686, in to_representation
    return [
  File "/Users/lijialin/myproject-flask/venv/lib/python3.8/site-packages/rest_framework/serializers.py", line 687, in <listcomp>
    self.child.to_representation(item) for item in iterable
  File "/Users/lijialin/myproject-flask/venv/lib/python3.8/site-packages/rest_framework/serializers.py", line 522, in to_representation
    ret[field.field_name] = field.to_representation(attribute)
  File "/Users/lijialin/myproject-flask/venv/lib/python3.8/site-packages/rest_framework/serializers.py", line 509, in to_representation
    attribute = field.get_attribute(instance)
  File "/Users/lijialin/myproject-flask/venv/lib/python3.8/site-packages/rest_framework/relations.py", line 538, in get_attribute
    relationship = get_attribute(instance, self.source_attrs)
  File "/Users/lijialin/myproject-flask/venv/lib/python3.8/site-packages/rest_framework/fields.py", line 97, in get_attribute
    instance = getattr(instance, attr)
AttributeError: 'User' object has no attribute 'drf_Article'
ERROR 2022-04-27 17:34:17,841 log 23448 6285438976 Internal Server Error: /v1/articles/
Traceback (most recent call last):
  File "/Users/lijialin/myproject-flask/venv/lib/python3.8/site-packages/django/core/handlers/exception.py", line 34, in inner
    response = get_response(request)
  File "/Users/lijialin/myproject-flask/venv/lib/python3.8/site-packages/django/core/handlers/base.py", line 115, in _get_response
    response = self.process_exception_by_middleware(e, request)
  File "/Users/lijialin/myproject-flask/venv/lib/python3.8/site-packages/django/core/handlers/base.py", line 113, in _get_response
    response = wrapped_callback(request, *callback_args, **callback_kwargs)
  File "/Users/lijialin/myproject-flask/venv/lib/python3.8/site-packages/django/views/decorators/csrf.py", line 54, in wrapped_view
    return view_func(*args, **kwargs)
  File "/Users/lijialin/myproject-flask/venv/lib/python3.8/site-packages/django/views/generic/base.py", line 71, in view
    return self.dispatch(request, *args, **kwargs)
  File "/Users/lijialin/myproject-flask/venv/lib/python3.8/site-packages/rest_framework/views.py", line 509, in dispatch
    response = self.handle_exception(exc)
  File "/Users/lijialin/myproject-flask/venv/lib/python3.8/site-packages/rest_framework/views.py", line 469, in handle_exception
    self.raise_uncaught_exception(exc)
  File "/Users/lijialin/myproject-flask/venv/lib/python3.8/site-packages/rest_framework/views.py", line 480, in raise_uncaught_exception
    raise exc
  File "/Users/lijialin/myproject-flask/venv/lib/python3.8/site-packages/rest_framework/views.py", line 506, in dispatch
    response = handler(request, *args, **kwargs)
  File "/Users/lijialin/myblog/drf/views.py", line 32, in get
    return Response(serializer.data)
  File "/Users/lijialin/myproject-flask/venv/lib/python3.8/site-packages/rest_framework/serializers.py", line 768, in data
    ret = super().data
  File "/Users/lijialin/myproject-flask/venv/lib/python3.8/site-packages/rest_framework/serializers.py", line 253, in data
    self._data = self.to_representation(self.instance)
  File "/Users/lijialin/myproject-flask/venv/lib/python3.8/site-packages/rest_framework/serializers.py", line 686, in to_representation
    return [
  File "/Users/lijialin/myproject-flask/venv/lib/python3.8/site-packages/rest_framework/serializers.py", line 687, in <listcomp>
    self.child.to_representation(item) for item in iterable
  File "/Users/lijialin/myproject-flask/venv/lib/python3.8/site-packages/rest_framework/serializers.py", line 522, in to_representation
    ret[field.field_name] = field.to_representation(attribute)
  File "/Users/lijialin/myproject-flask/venv/lib/python3.8/site-packages/rest_framework/serializers.py", line 509, in to_representation
    attribute = field.get_attribute(instance)
  File "/Users/lijialin/myproject-flask/venv/lib/python3.8/site-packages/rest_framework/relations.py", line 538, in get_attribute
    relationship = get_attribute(instance, self.source_attrs)
  File "/Users/lijialin/myproject-flask/venv/lib/python3.8/site-packages/rest_framework/fields.py", line 97, in get_attribute
    instance = getattr(instance, attr)
AttributeError: 'User' object has no attribute 'drf_Article'
ERROR 2022-04-27 17:36:07,607 log 23473 6244757504 Internal Server Error: /v1/articles/
Traceback (most recent call last):
  File "/Users/lijialin/myproject-flask/venv/lib/python3.8/site-packages/django/core/handlers/exception.py", line 34, in inner
    response = get_response(request)
  File "/Users/lijialin/myproject-flask/venv/lib/python3.8/site-packages/django/core/handlers/base.py", line 115, in _get_response
    response = self.process_exception_by_middleware(e, request)
  File "/Users/lijialin/myproject-flask/venv/lib/python3.8/site-packages/django/core/handlers/base.py", line 113, in _get_response
    response = wrapped_callback(request, *callback_args, **callback_kwargs)
  File "/Users/lijialin/myproject-flask/venv/lib/python3.8/site-packages/django/views/decorators/csrf.py", line 54, in wrapped_view
    return view_func(*args, **kwargs)
  File "/Users/lijialin/myproject-flask/venv/lib/python3.8/site-packages/django/views/generic/base.py", line 71, in view
    return self.dispatch(request, *args, **kwargs)
  File "/Users/lijialin/myproject-flask/venv/lib/python3.8/site-packages/rest_framework/views.py", line 509, in dispatch
    response = self.handle_exception(exc)
  File "/Users/lijialin/myproject-flask/venv/lib/python3.8/site-packages/rest_framework/views.py", line 469, in handle_exception
    self.raise_uncaught_exception(exc)
  File "/Users/lijialin/myproject-flask/venv/lib/python3.8/site-packages/rest_framework/views.py", line 480, in raise_uncaught_exception
    raise exc
  File "/Users/lijialin/myproject-flask/venv/lib/python3.8/site-packages/rest_framework/views.py", line 506, in dispatch
    response = handler(request, *args, **kwargs)
  File "/Users/lijialin/myblog/drf/views.py", line 32, in get
    return Response(serializer.data)
  File "/Users/lijialin/myproject-flask/venv/lib/python3.8/site-packages/rest_framework/serializers.py", line 768, in data
    ret = super().data
  File "/Users/lijialin/myproject-flask/venv/lib/python3.8/site-packages/rest_framework/serializers.py", line 253, in data
    self._data = self.to_representation(self.instance)
  File "/Users/lijialin/myproject-flask/venv/lib/python3.8/site-packages/rest_framework/serializers.py", line 686, in to_representation
    return [
  File "/Users/lijialin/myproject-flask/venv/lib/python3.8/site-packages/rest_framework/serializers.py", line 687, in <listcomp>
    self.child.to_representation(item) for item in iterable
  File "/Users/lijialin/myproject-flask/venv/lib/python3.8/site-packages/rest_framework/serializers.py", line 522, in to_representation
    ret[field.field_name] = field.to_representation(attribute)
  File "/Users/lijialin/myproject-flask/venv/lib/python3.8/site-packages/rest_framework/serializers.py", line 509, in to_representation
    attribute = field.get_attribute(instance)
  File "/Users/lijialin/myproject-flask/venv/lib/python3.8/site-packages/rest_framework/relations.py", line 538, in get_attribute
    relationship = get_attribute(instance, self.source_attrs)
  File "/Users/lijialin/myproject-flask/venv/lib/python3.8/site-packages/rest_framework/fields.py", line 97, in get_attribute
    instance = getattr(instance, attr)
AttributeError: 'User' object has no attribute 'articles'
ERROR 2022-04-27 17:36:57,162 log 23510 6216986624 Internal Server Error: /v1/articles/
Traceback (most recent call last):
  File "/Users/lijialin/myproject-flask/venv/lib/python3.8/site-packages/django/core/handlers/exception.py", line 34, in inner
    response = get_response(request)
  File "/Users/lijialin/myproject-flask/venv/lib/python3.8/site-packages/django/core/handlers/base.py", line 115, in _get_response
    response = self.process_exception_by_middleware(e, request)
  File "/Users/lijialin/myproject-flask/venv/lib/python3.8/site-packages/django/core/handlers/base.py", line 113, in _get_response
    response = wrapped_callback(request, *callback_args, **callback_kwargs)
  File "/Users/lijialin/myproject-flask/venv/lib/python3.8/site-packages/django/views/decorators/csrf.py", line 54, in wrapped_view
    return view_func(*args, **kwargs)
  File "/Users/lijialin/myproject-flask/venv/lib/python3.8/site-packages/django/views/generic/base.py", line 71, in view
    return self.dispatch(request, *args, **kwargs)
  File "/Users/lijialin/myproject-flask/venv/lib/python3.8/site-packages/rest_framework/views.py", line 509, in dispatch
    response = self.handle_exception(exc)
  File "/Users/lijialin/myproject-flask/venv/lib/python3.8/site-packages/rest_framework/views.py", line 469, in handle_exception
    self.raise_uncaught_exception(exc)
  File "/Users/lijialin/myproject-flask/venv/lib/python3.8/site-packages/rest_framework/views.py", line 480, in raise_uncaught_exception
    raise exc
  File "/Users/lijialin/myproject-flask/venv/lib/python3.8/site-packages/rest_framework/views.py", line 506, in dispatch
    response = handler(request, *args, **kwargs)
  File "/Users/lijialin/myblog/drf/views.py", line 32, in get
    return Response(serializer.data)
  File "/Users/lijialin/myproject-flask/venv/lib/python3.8/site-packages/rest_framework/serializers.py", line 768, in data
    ret = super().data
  File "/Users/lijialin/myproject-flask/venv/lib/python3.8/site-packages/rest_framework/serializers.py", line 253, in data
    self._data = self.to_representation(self.instance)
  File "/Users/lijialin/myproject-flask/venv/lib/python3.8/site-packages/rest_framework/serializers.py", line 686, in to_representation
    return [
  File "/Users/lijialin/myproject-flask/venv/lib/python3.8/site-packages/rest_framework/serializers.py", line 687, in <listcomp>
    self.child.to_representation(item) for item in iterable
  File "/Users/lijialin/myproject-flask/venv/lib/python3.8/site-packages/rest_framework/serializers.py", line 522, in to_representation
    ret[field.field_name] = field.to_representation(attribute)
  File "/Users/lijialin/myproject-flask/venv/lib/python3.8/site-packages/rest_framework/serializers.py", line 509, in to_representation
    attribute = field.get_attribute(instance)
  File "/Users/lijialin/myproject-flask/venv/lib/python3.8/site-packages/rest_framework/relations.py", line 538, in get_attribute
    relationship = get_attribute(instance, self.source_attrs)
  File "/Users/lijialin/myproject-flask/venv/lib/python3.8/site-packages/rest_framework/fields.py", line 97, in get_attribute
    instance = getattr(instance, attr)
AttributeError: 'User' object has no attribute 'articles'
WARNING 2022-04-28 15:03:27,389 log 26670 6246215680 Not Found: /v1/api-auth
WARNING 2022-04-28 15:03:59,122 log 26702 6249787392 Not Found: /v1/api-auth/
WARNING 2022-04-28 15:04:32,360 log 26702 6249787392 Not Found: /accounts/profile/
WARNING 2022-04-28 15:07:45,739 log 26793 6240022528 Not Found: /accounts/profile/
WARNING 2022-04-28 15:09:24,229 log 26839 6215217152 Not Found: /accounts/profile/
WARNING 2022-04-28 15:09:36,610 log 26839 6215217152 Not Found: /accounts/profile/
WARNING 2022-04-28 15:36:15,527 log 27117 6210990080 Not Found: /accounts/profile/
ERROR 2022-04-28 15:36:58,839 log 27117 6210990080 Internal Server Error: /v1/articles/1
Traceback (most recent call last):
  File "/Users/lijialin/myproject-flask/venv/lib/python3.8/site-packages/rest_framework/fields.py", line 457, in get_attribute
    return get_attribute(instance, self.source_attrs)
  File "/Users/lijialin/myproject-flask/venv/lib/python3.8/site-packages/rest_framework/fields.py", line 97, in get_attribute
    instance = getattr(instance, attr)
AttributeError: type object 'Http404' has no attribute 'title'

During handling of the above exception, another exception occurred:

Traceback (most recent call last):
  File "/Users/lijialin/myproject-flask/venv/lib/python3.8/site-packages/django/core/handlers/exception.py", line 34, in inner
    response = get_response(request)
  File "/Users/lijialin/myproject-flask/venv/lib/python3.8/site-packages/django/core/handlers/base.py", line 115, in _get_response
    response = self.process_exception_by_middleware(e, request)
  File "/Users/lijialin/myproject-flask/venv/lib/python3.8/site-packages/django/core/handlers/base.py", line 113, in _get_response
    response = wrapped_callback(request, *callback_args, **callback_kwargs)
  File "/Users/lijialin/myproject-flask/venv/lib/python3.8/site-packages/django/views/decorators/csrf.py", line 54, in wrapped_view
    return view_func(*args, **kwargs)
  File "/Users/lijialin/myproject-flask/venv/lib/python3.8/site-packages/django/views/generic/base.py", line 71, in view
    return self.dispatch(request, *args, **kwargs)
  File "/Users/lijialin/myproject-flask/venv/lib/python3.8/site-packages/rest_framework/views.py", line 509, in dispatch
    response = self.handle_exception(exc)
  File "/Users/lijialin/myproject-flask/venv/lib/python3.8/site-packages/rest_framework/views.py", line 469, in handle_exception
    self.raise_uncaught_exception(exc)
  File "/Users/lijialin/myproject-flask/venv/lib/python3.8/site-packages/rest_framework/views.py", line 480, in raise_uncaught_exception
    raise exc
  File "/Users/lijialin/myproject-flask/venv/lib/python3.8/site-packages/rest_framework/views.py", line 506, in dispatch
    response = handler(request, *args, **kwargs)
  File "/Users/lijialin/myblog/drf/views.py", line 82, in get
    return Response(serializer.data)
  File "/Users/lijialin/myproject-flask/venv/lib/python3.8/site-packages/rest_framework/serializers.py", line 555, in data
    ret = super().data
  File "/Users/lijialin/myproject-flask/venv/lib/python3.8/site-packages/rest_framework/serializers.py", line 253, in data
    self._data = self.to_representation(self.instance)
  File "/Users/lijialin/myproject-flask/venv/lib/python3.8/site-packages/rest_framework/serializers.py", line 509, in to_representation
    attribute = field.get_attribute(instance)
  File "/Users/lijialin/myproject-flask/venv/lib/python3.8/site-packages/rest_framework/fields.py", line 490, in get_attribute
    raise type(exc)(msg)
AttributeError: Got AttributeError when attempting to get a value for field `title` on serializer `ArticleSerializer`.
The serializer field might be named incorrectly and not match any attribute or key on the `type` instance.
Original exception text was: type object 'Http404' has no attribute 'title'.
ERROR 2022-05-12 20:21:40,641 log 8703 6281687040 Internal Server Error: /v1/articles/
Traceback (most recent call last):
  File "/Users/lijialin/myproject-flask/venv/lib/python3.8/site-packages/django/core/handlers/exception.py", line 34, in inner
    response = get_response(request)
  File "/Users/lijialin/myproject-flask/venv/lib/python3.8/site-packages/django/core/handlers/base.py", line 115, in _get_response
    response = self.process_exception_by_middleware(e, request)
  File "/Users/lijialin/myproject-flask/venv/lib/python3.8/site-packages/django/core/handlers/base.py", line 113, in _get_response
    response = wrapped_callback(request, *callback_args, **callback_kwargs)
  File "/Users/lijialin/myproject-flask/venv/lib/python3.8/site-packages/django/views/decorators/csrf.py", line 54, in wrapped_view
    return view_func(*args, **kwargs)
  File "/Users/lijialin/myproject-flask/venv/lib/python3.8/site-packages/django/views/generic/base.py", line 71, in view
    return self.dispatch(request, *args, **kwargs)
  File "/Users/lijialin/myproject-flask/venv/lib/python3.8/site-packages/rest_framework/views.py", line 509, in dispatch
    response = self.handle_exception(exc)
  File "/Users/lijialin/myproject-flask/venv/lib/python3.8/site-packages/rest_framework/views.py", line 469, in handle_exception
    self.raise_uncaught_exception(exc)
  File "/Users/lijialin/myproject-flask/venv/lib/python3.8/site-packages/rest_framework/views.py", line 480, in raise_uncaught_exception
    raise exc
  File "/Users/lijialin/myproject-flask/venv/lib/python3.8/site-packages/rest_framework/views.py", line 506, in dispatch
    response = handler(request, *args, **kwargs)
  File "/Users/lijialin/myblog/drf/views.py", line 43, in get
    'user': unicode(request.user),  # `django.contrib.auth.User` 实例。
NameError: name 'unicode' is not defined
ERROR 2022-05-12 20:25:59,874 log 8829 6287175680 Internal Server Error: /v1/articles/
Traceback (most recent call last):
  File "/Users/lijialin/myproject-flask/venv/lib/python3.8/site-packages/django/core/handlers/exception.py", line 34, in inner
    response = get_response(request)
  File "/Users/lijialin/myproject-flask/venv/lib/python3.8/site-packages/django/core/handlers/base.py", line 145, in _get_response
    response = self.process_exception_by_middleware(e, request)
  File "/Users/lijialin/myproject-flask/venv/lib/python3.8/site-packages/django/core/handlers/base.py", line 143, in _get_response
    response = response.render()
  File "/Users/lijialin/myproject-flask/venv/lib/python3.8/site-packages/django/template/response.py", line 106, in render
    self.content = self.rendered_content
  File "/Users/lijialin/myproject-flask/venv/lib/python3.8/site-packages/rest_framework/response.py", line 70, in rendered_content
    ret = renderer.render(self.data, accepted_media_type, context)
  File "/Users/lijialin/myproject-flask/venv/lib/python3.8/site-packages/rest_framework/renderers.py", line 724, in render
    context = self.get_context(data, accepted_media_type, renderer_context)
  File "/Users/lijialin/myproject-flask/venv/lib/python3.8/site-packages/rest_framework/renderers.py", line 680, in get_context
    'content': self.get_content(renderer, data, accepted_media_type, renderer_context),
  File "/Users/lijialin/myproject-flask/venv/lib/python3.8/site-packages/rest_framework/renderers.py", line 413, in get_content
    content = renderer.render(data, accepted_media_type, renderer_context)
  File "/Users/lijialin/myproject-flask/venv/lib/python3.8/site-packages/rest_framework/renderers.py", line 100, in render
    ret = json.dumps(
  File "/Users/lijialin/myproject-flask/venv/lib/python3.8/site-packages/rest_framework/utils/json.py", line 25, in dumps
    return json.dumps(*args, **kwargs)
  File "/Library/Developer/CommandLineTools/Library/Frameworks/Python3.framework/Versions/3.8/lib/python3.8/json/__init__.py", line 234, in dumps
    return cls(
  File "/Library/Developer/CommandLineTools/Library/Frameworks/Python3.framework/Versions/3.8/lib/python3.8/json/encoder.py", line 201, in encode
    chunks = list(chunks)
  File "/Library/Developer/CommandLineTools/Library/Frameworks/Python3.framework/Versions/3.8/lib/python3.8/json/encoder.py", line 431, in _iterencode
    yield from _iterencode_dict(o, _current_indent_level)
  File "/Library/Developer/CommandLineTools/Library/Frameworks/Python3.framework/Versions/3.8/lib/python3.8/json/encoder.py", line 405, in _iterencode_dict
    yield from chunks
  File "/Library/Developer/CommandLineTools/Library/Frameworks/Python3.framework/Versions/3.8/lib/python3.8/json/encoder.py", line 438, in _iterencode
    o = _default(o)
  File "/Users/lijialin/myproject-flask/venv/lib/python3.8/site-packages/rest_framework/utils/encoders.py", line 67, in default
    return super().default(obj)
  File "/Library/Developer/CommandLineTools/Library/Frameworks/Python3.framework/Versions/3.8/lib/python3.8/json/encoder.py", line 179, in default
    raise TypeError(f'Object of type {o.__class__.__name__} '
TypeError: Object of type User is not JSON serializable
WARNING 2022-05-13 15:58:45,349 log 4799 6207827968 Not Found: /media/article/20220414/download-2.jpg
WARNING 2022-05-13 15:58:45,652 log 4799 6258307072 Not Found: /favicon.ico
WARNING 2022-08-05 14:42:32,216 log 2728 6199275520 Not Found: /
WARNING 2022-08-05 14:42:32,290 log 2728 6199275520 Not Found: /favicon.ico
WARNING 2022-08-05 14:42:38,662 log 2728 6199275520 Not Found: /acrticles
WARNING 2022-08-05 14:42:44,880 log 2728 6199275520 Not Found: /acrticle/
WARNING 2022-08-05 14:43:04,157 log 2728 6199275520 Not Found: /article/list
WARNING 2022-08-05 14:43:37,081 log 2728 6199275520 Not Found: /article-list
WARNING 2022-08-05 14:47:01,994 log 2877 6193655808 Not Found: /
